Workbook
Name MonthlyChart_Data1: OFFSET(#REF!,0,0,1,MonthsWithActual)
Name MonthsWithActual: COUNTIF(#REF!,"<>"&0)

Sheet Raw Data
A1: Month | B1: Development Costs | C1: Operatinal Costs | D1: Marketing Costs | E1: Travelling Cost | F1: Training Cost | G1: Maintenance Cost | H1: Expenses
A2: 44927 | B2: 107000 | C2: 12000 | D2: 10000 | E2: 4000 | F2: 6000 | G2: 4000 | H2: Budget
A3: 44958 | B3: 107000 | C3: 12000 | D3: 5000 | E3: 4000 | F3: 6000 | G3: 4000 | H3: Budget
A4: 44986 | B4: 108000 | C4: 12000 | D4: 5000 | E4: 4000 | F4: 6000 | G4: 4000 | H4: Budget
A5: 45017 | B5: 107000 | C5: 12000 | D5: 10000 | E5: 4000 | F5: 6000 | G5: 4000 | H5: Budget
A6: 45047 | B6: 111100 | C6: 12000 | D6: 4000 | E6: 4000 | F6: 6000 | G6: 4000 | H6: Budget
A7: 45078 | B7: 111100 | C7: 15000 | D7: 4000 | E7: 4000 | F7: 8000 | G7: 4000 | H7: Budget
A8: 45108 | B8: 110000 | C8: 15000 | D8: 8000 | E8: 4000 | F8: 8000 | G8: 4000 | H8: Budget
A9: 45139 | B9: 117000 | C9: 15000 | D9: 6000 | E9: 4000 | F9: 8000 | G9: 4000 | H9: Budget
A10: 45170 | B10: 118000 | C10: 15000 | D10: 3000 | E10: 4000 | F10: 8000 | G10: 4000 | H10: Budget
A11: 45200 | B11: 110000 | C11: 15000 | D11: 10000 | E11: 4000 | F11: 8000 | G11: 4000 | H11: Budget
A12: 45231 | B12: 117000 | C12: 15000 | D12: 3000 | E12: 4000 | F12: 8000 | G12: 4000 | H12: Budget
A13: 45261 | B13: 117000 | C13: 15000 | D13: 7000 | E13: 4000 | F13: 8000 | G13: 4000 | H13: Budget
... A25: 45261 | B25: 113000 | C25: 14200 | D25: 7200 | E25: 4800 | F25: 7500 | G25: 4590 | H25: Actual

Sheet Clean Data
A1: Month | B1: Month Number | C1: Development Costs | D1: Operational Costs | E1: Marketing Costs | F1: Travelling Cost | G1: Training Cost | H1: Maintenance Cost | I1: Type
A2: 44927 | B2: =MONTH(A2) -> 1 | C2: 107000 | D2: 12000 | E2: 10000 | F2: 4000 | G2: 6000 | H2: 4000 | I2: Budget
A3: 44958 | B3: =MONTH(A3) -> 2 | C3: 107000 | D3: 12000 | E3: 5000 | F3: 4000 | G3: 6000 | H3: 4000 | I3: Budget
A4: 44986 | B4: =MONTH(A4) -> 3 | C4: 108000 | D4: 12000 | E4: 5000 | F4: 4000 | G4: 6000 | H4: 4000 | I4: Budget
A5: 45017 | B5: =MONTH(A5) -> 4 | C5: 107000 | D5: 12000 | E5: 10000 | F5: 4000 | G5: 6000 | H5: 4000 | I5: Budget
A6: 45047 | B6: =MONTH(A6) -> 5 | C6: 111100 | D6: 12000 | E6: 4000 | F6: 4000 | G6: 6000 | H6: 4000 | I6: Budget
A7: 45078 | B7: =MONTH(A7) -> 6 | C7: 111100 | D7: 15000 | E7: 4000 | F7: 4000 | G7: 8000 | H7: 4000 | I7: Budget
A8: 45108 | B8: =MONTH(A8) -> 7 | C8: 110000 | D8: 15000 | E8: 8000 | F8: 4000 | G8: 8000 | H8: 4000 | I8: Budget
A9: 45139 | B9: =MONTH(A9) -> 8 | C9: 117000 | D9: 15000 | E9: 6000 | F9: 4000 | G9: 8000 | H9: 4000 | I9: Budget
A10: 45170 | B10: =MONTH(A10) -> 9 | C10: 118000 | D10: 15000 | E10: 3000 | F10: 4000 | G10: 8000 | H10: 4000 | I10: Budget
A11: 45200 | B11: =MONTH(A11) -> 10 | C11: 110000 | D11: 15000 | E11: 10000 | F11: 4000 | G11: 8000 | H11: 4000 | I11: Budget
A12: 45231 | B12: =MONTH(A12) -> 11 | C12: 117000 | D12: 15000 | E12: 3000 | F12: 4000 | G12: 8000 | H12: 4000 | I12: Budget
A13: 45261 | B13: =MONTH(A13) -> 12 | C13: 117000 | D13: 15000 | E13: 7000 | F13: 4000 | G13: 8000 | H13: 4000 | I13: Budget
... A25: 45261 | B25: =MONTH(A25) -> 12 | C25: 113000 | D25: 14200 | E25: 7200 | F25: 4800 | G25: 7500 | H25: 4590 | I25: Actual

Sheet Pivot
A1: Type | B1: Budget
A3: Row Labels | B3: Sum of Development Costs | C3: Sum of Operational Costs | D3: Sum of Marketing Costs | E3: Sum of Travelling Cost | F3: Sum of Training Cost | G3: Sum of Maintenance Cost
A4: 1 | B4: 107000 | C4: 12000 | D4: 10000 | E4: 4000 | F4: 6000 | G4: 4000
A5: 2 | B5: 107000 | C5: 12000 | D5: 5000 | E5: 4000 | F5: 6000 | G5: 4000
A6: 3 | B6: 108000 | C6: 12000 | D6: 5000 | E6: 4000 | F6: 6000 | G6: 4000
A7: 4 | B7: 107000 | C7: 12000 | D7: 10000 | E7: 4000 | F7: 6000 | G7: 4000
A8: 5 | B8: 111100 | C8: 12000 | D8: 4000 | E8: 4000 | F8: 6000 | G8: 4000
A9: 6 | B9: 111100 | C9: 15000 | D9: 4000 | E9: 4000 | F9: 8000 | G9: 4000
A10: 7 | B10: 110000 | C10: 15000 | D10: 8000 | E10: 4000 | F10: 8000 | G10: 4000
A11: 8 | B11: 117000 | C11: 15000 | D11: 6000 | E11: 4000 | F11: 8000 | G11: 4000
A12: 9 | B12: 118000 | C12: 15000 | D12: 3000 | E12: 4000 | F12: 8000 | G12: 4000
A13: 10 | B13: 110000 | C13: 15000 | D13: 10000 | E13: 4000 | F13: 8000 | G13: 4000
A14: 11 | B14: 117000 | C14: 15000 | D14: 3000 | E14: 4000 | F14: 8000 | G14: 4000
A15: 12 | B15: 117000 | C15: 15000 | D15: 7000 | E15: 4000 | F15: 8000 | G15: 4000
A16: Grand Total | B16: 1340200 | C16: 165000 | D16: 75000 | E16: 48000 | F16: 86000 | G16: 48000
A18: Type | B18: Actual
A20: Row Labels | B20: Sum of Development Costs | C20: Sum of Operational Costs | D20: Sum of Marketing Costs | E20: Sum of Travelling Cost | F20: Sum of Training Cost | G20: Sum of Maintenance Cost
A21: 1 | B21: 106950 | C21: 15600 | D21: 9820 | E21: 3200 | F21: 5500 | G21: 3200
A22: 2 | B22: 109000 | C22: 11698 | D22: 3556 | E22: 2300 | F22: 6500 | G22: 2800
A23: 3 | B23: 108500 | C23: 13453 | D23: 6800 | E23: 5300 | F23: 0 | G23: 7800
A24: 4 | B24: 109900 | C24: 15790 | D24: 11400 | E24: 2200 | F24: 4000 | G24: 5700
A25: 5 | B25: 111760 | C25: 11508 | D25: 2900 | E25: 1200 | F25: 6000 | G25: 4600
A26: 6 | B26: 111760 | C26: 15500 | D26: 3500 | E26: 4200 | F26: 6500 | G26: 5500
A27: 7 | B27: 102000 | C27: 14333 | D27: 3000 | E27: 2900 | F27: 7500 | G27: 4000
A28: 8 | B28: 108100 | C28: 16500 | D28: 5800 | E28: 4300 | F28: 6000 | G28: 3100
A29: 9 | B29: 114070 | C29: 10900 | D29: 3000 | E29: 2700 | F29: 7000 | G29: 2400
A30: 10 | B30: 104040 | C30: 17800 | D30: 9800 | E30: 3700 | F30: 5500 | G30: 1398
A31: 11 | B31: 115555 | C31: 16800 | D31: 2900 | E31: 4500 | F31: 6000 | G31: 5399
A32: 12 | B32: 113000 | C32: 14200 | D32: 7200 | E32: 4800 | F32: 7500 | G32: 4590
A33: Grand Total | B33: 1314635 | C33: 174082 | D33: 69676 | E33: 41300 | F33: 68000 | G33: 50487

Sheet Budget Analysis
A2: Month | B2: Category | C2: Budget | D2: Actual | E2: Variance | F2: Variance % | G2: Status
A3: =Pivot!A4 -> 1 | B3: Development Costs | C3: =Pivot!B4 -> 107000 | D3: =VLOOKUP(A3,Pivot!$A$21:$G$32,2,0) -> 106950 | E3: =D3-C3 -> -50 | F3: =E3/C3 -> -0.00046728972 | G3: =IF(F3>0.1,"Over Budget",IF(F3<-0.1,"Under Budget","On Track")) -> On Track
A4: =Pivot!A5 -> 2 | B4: Development Costs | C4: =Pivot!B5 -> 107000 | D4: =VLOOKUP(A4,Pivot!$A$21:$G$32,2,0) -> 109000 | E4: =D4-C4 -> 2000 | F4: =E4/C4 -> 0.018691589 | G4: =IF(F4>0.1,"Over Budget",IF(F4<-0.1,"Under Budget","On Track")) -> On Track
A5: =Pivot!A6 -> 3 | B5: Development Costs | C5: =Pivot!B6 -> 108000 | D5: =VLOOKUP(A5,Pivot!$A$21:$G$32,2,0) -> 108500 | E5: =D5-C5 -> 500 | F5: =E5/C5 -> 0.0046296296 | G5: =IF(F5>0.1,"Over Budget",IF(F5<-0.1,"Under Budget","On Track")) -> On Track
A6: =Pivot!A7 -> 4 | B6: Development Costs | C6: =Pivot!B7 -> 107000 | D6: =VLOOKUP(A6,Pivot!$A$21:$G$32,2,0) -> 109900 | E6: =D6-C6 -> 2900 | F6: =E6/C6 -> 0.027102804 | G6: =IF(F6>0.1,"Over Budget",IF(F6<-0.1,"Under Budget","On Track")) -> On Track
A7: =Pivot!A8 -> 5 | B7: Development Costs | C7: =Pivot!B8 -> 111100 | D7: =VLOOKUP(A7,Pivot!$A$21:$G$32,2,0) -> 111760 | E7: =D7-C7 -> 660 | F7: =E7/C7 -> 0.0059405941 | G7: =IF(F7>0.1,"Over Budget",IF(F7<-0.1,"Under Budget","On Track")) -> On Track
A8: =Pivot!A9 -> 6 | B8: Development Costs | C8: =Pivot!B9 -> 111100 | D8: =VLOOKUP(A8,Pivot!$A$21:$G$32,2,0) -> 111760 | E8: =D8-C8 -> 660 | F8: =E8/C8 -> 0.0059405941 | G8: =IF(F8>0.1,"Over Budget",IF(F8<-0.1,"Under Budget","On Track")) -> On Track
A9: =Pivot!A10 -> 7 | B9: Development Costs | C9: =Pivot!B10 -> 110000 | D9: =VLOOKUP(A9,Pivot!$A$21:$G$32,2,0) -> 102000 | E9: =D9-C9 -> -8000 | F9: =E9/C9 -> -0.072727273 | G9: =IF(F9>0.1,"Over Budget",IF(F9<-0.1,"Under Budget","On Track")) -> On Track
A10: =Pivot!A11 -> 8 | B10: Development Costs | C10: =Pivot!B11 -> 117000 | D10: =VLOOKUP(A10,Pivot!$A$21:$G$32,2,0) -> 108100 | E10: =D10-C10 -> -8900 | F10: =E10/C10 -> -0.076068376 | G10: =IF(F10>0.1,"Over Budget",IF(F10<-0.1,"Under Budget","On Track")) -> On Track
A11: =Pivot!A12 -> 9 | B11: Development Costs | C11: =Pivot!B12 -> 118000 | D11: =VLOOKUP(A11,Pivot!$A$21:$G$32,2,0) -> 114070 | E11: =D11-C11 -> -3930 | F11: =E11/C11 -> -0.033305085 | G11: =IF(F11>0.1,"Over Budget",IF(F11<-0.1,"Under Budget","On Track")) -> On Track
A12: =Pivot!A13 -> 10 | B12: Development Costs | C12: =Pivot!B13 -> 110000 | D12: =VLOOKUP(A12,Pivot!$A$21:$G$32,2,0) -> 104040 | E12: =D12-C12 -> -5960 | F12: =E12/C12 -> -0.054181818 | G12: =IF(F12>0.1,"Over Budget",IF(F12<-0.1,"Under Budget","On Track")) -> On Track
A13: =Pivot!A14 -> 11 | B13: Development Costs | C13: =Pivot!B14 -> 117000 | D13: =VLOOKUP(A13,Pivot!$A$21:$G$32,2,0) -> 115555 | E13: =D13-C13 -> -1445 | F13: =E13/C13 -> -0.012350427 | G13: =IF(F13>0.1,"Over Budget",IF(F13<-0.1,"Under Budget","On Track")) -> On Track
A14: =Pivot!A15 -> 12 | B14: Development Costs | C14: =Pivot!B15 -> 117000 | D14: =VLOOKUP(A14,Pivot!$A$21:$G$32,2,0) -> 113000 | E14: =D14-C14 -> -4000 | F14: =E14/C14 -> -0.034188034 | G14: =IF(F14>0.1,"Over Budget",IF(F14<-0.1,"Under Budget","On Track")) -> On Track
A15: =Pivot!A4 -> 1 | B15: Operational Costs | C15: =Pivot!C4 -> 12000 | D15: =VLOOKUP(A3,Pivot!$A$21:$G$32,3,0) -> 15600 | E15: =D15-C15 -> 3600 | F15: =E15/C15 -> 0.3 | G15: =IF(F15>0.1,"Over Budget",IF(F15<-0.1,"Under Budget","On Track")) -> Over Budget
A16: =Pivot!A5 -> 2 | B16: Operational Costs | C16: =Pivot!C5 -> 12000 | D16: =VLOOKUP(A4,Pivot!$A$21:$G$32,3,0) -> 11698 | E16: =D16-C16 -> -302 | F16: =E16/C16 -> -0.025166667 | G16: =IF(F16>0.1,"Over Budget",IF(F16<-0.1,"Under Budget","On Track")) -> On Track
A17: =Pivot!A6 -> 3 | B17: Operational Costs | C17: =Pivot!C6 -> 12000 | D17: =VLOOKUP(A5,Pivot!$A$21:$G$32,3,0) -> 13453 | E17: =D17-C17 -> 1453 | F17: =E17/C17 -> 0.12108333 | G17: =IF(F17>0.1,"Over Budget",IF(F17<-0.1,"Under Budget","On Track")) -> Over Budget
A18: =Pivot!A7 -> 4 | B18: Operational Costs | C18: =Pivot!C7 -> 12000 | D18: =VLOOKUP(A6,Pivot!$A$21:$G$32,3,0) -> 15790 | E18: =D18-C18 -> 3790 | F18: =E18/C18 -> 0.31583333 | G18: =IF(F18>0.1,"Over Budget",IF(F18<-0.1,"Under Budget","On Track")) -> Over Budget
A19: =Pivot!A8 -> 5 | B19: Operational Costs | C19: =Pivot!C8 -> 12000 | D19: =VLOOKUP(A7,Pivot!$A$21:$G$32,3,0) -> 11508 | E19: =D19-C19 -> -492 | F19: =E19/C19 -> -0.041 | G19: =IF(F19>0.1,"Over Budget",IF(F19<-0.1,"Under Budget","On Track")) -> On Track
A20: =Pivot!A9 -> 6 | B20: Operational Costs | C20: =Pivot!C9 -> 15000 | D20: =VLOOKUP(A8,Pivot!$A$21:$G$32,3,0) -> 15500 | E20: =D20-C20 -> 500 | F20: =E20/C20 -> 0.033333333 | G20: =IF(F20>0.1,"Over Budget",IF(F20<-0.1,"Under Budget","On Track")) -> On Track
A21: =Pivot!A10 -> 7 | B21: Operational Costs | C21: =Pivot!C10 -> 15000 | D21: =VLOOKUP(A9,Pivot!$A$21:$G$32,3,0) -> 14333 | E21: =D21-C21 -> -667 | F21: =E21/C21 -> -0.044466667 | G21: =IF(F21>0.1,"Over Budget",IF(F21<-0.1,"Under Budget","On Track")) -> On Track
A22: =Pivot!A11 -> 8 | B22: Operational Costs | C22: =Pivot!C11 -> 15000 | D22: =VLOOKUP(A10,Pivot!$A$21:$G$32,3,0) -> 16500 | E22: =D22-C22 -> 1500 | F22: =E22/C22 -> 0.1 | G22: =IF(F22>0.1,"Over Budget",IF(F22<-0.1,"Under Budget","On Track")) -> On Track
A23: =Pivot!A12 -> 9 | B23: Operational Costs | C23: =Pivot!C12 -> 15000 | D23: =VLOOKUP(A11,Pivot!$A$21:$G$32,3,0) -> 10900 | E23: =D23-C23 -> -4100 | F23: =E23/C23 -> -0.27333333 | G23: =IF(F23>0.1,"Over Budget",IF(F23<-0.1,"Under Budget","On Track")) -> Under Budget
A24: =Pivot!A13 -> 10 | B24: Operational Costs | C24: =Pivot!C13 -> 15000 | D24: =VLOOKUP(A12,Pivot!$A$21:$G$32,3,0) -> 17800 | E24: =D24-C24 -> 2800 | F24: =E24/C24 -> 0.18666667 | G24: =IF(F24>0.1,"Over Budget",IF(F24<-0.1,"Under Budget","On Track")) -> Over Budget
A25: =Pivot!A14 -> 11 | B25: Operational Costs | C25: =Pivot!C14 -> 15000 | D25: =VLOOKUP(A13,Pivot!$A$21:$G$32,3,0) -> 16800 | E25: =D25-C25 -> 1800 | F25: =E25/C25 -> 0.12 | G25: =IF(F25>0.1,"Over Budget",IF(F25<-0.1,"Under Budget","On Track")) -> Over Budget
A26: =Pivot!A15 -> 12 | B26: Operational Costs | C26: =Pivot!C15 -> 15000 | D26: =VLOOKUP(A14,Pivot!$A$21:$G$32,3,0) -> 14200 | E26: =D26-C26 -> -800 | F26: =E26/C26 -> -0.053333333 | G26: =IF(F26>0.1,"Over Budget",IF(F26<-0.1,"Under Budget","On Track")) -> On Track
A27: =Pivot!A4 -> 1 | B27: Marketing Costs | C27: =Pivot!D4 -> 10000 | D27: =VLOOKUP(A3,Pivot!$A$21:$G$32,4,0) -> 9820 | E27: =D27-C27 -> -180 | F27: =E27/C27 -> -0.018 | G27: =IF(F27>0.1,"Over Budget",IF(F27<-0.1,"Under Budget","On Track")) -> On Track
A28: =Pivot!A5 -> 2 | B28: Marketing Costs | C28: =Pivot!D5 -> 5000 | D28: =VLOOKUP(A4,Pivot!$A$21:$G$32,4,0) -> 3556 | E28: =D28-C28 -> -1444 | F28: =E28/C28 -> -0.2888 | G28: =IF(F28>0.1,"Over Budget",IF(F28<-0.1,"Under Budget","On Track")) -> Under Budget
A29: =Pivot!A6 -> 3 | B29: Marketing Costs | C29: =Pivot!D6 -> 5000 | D29: =VLOOKUP(A5,Pivot!$A$21:$G$32,4,0) -> 6800 | E29: =D29-C29 -> 1800 | F29: =E29/C29 -> 0.36 | G29: =IF(F29>0.1,"Over Budget",IF(F29<-0.1,"Under Budget","On Track")) -> Over Budget
A30: =Pivot!A7 -> 4 | B30: Marketing Costs | C30: =Pivot!D7 -> 10000 | D30: =VLOOKUP(A6,Pivot!$A$21:$G$32,4,0) -> 11400 | E30: =D30-C30 -> 1400 | F30: =E30/C30 -> 0.14 | G30: =IF(F30>0.1,"Over Budget",IF(F30<-0.1,"Under Budget","On Track")) -> Over Budget
A31: =Pivot!A8 -> 5 | B31: Marketing Costs | C31: =Pivot!D8 -> 4000 | D31: =VLOOKUP(A7,Pivot!$A$21:$G$32,4,0) -> 2900 | E31: =D31-C31 -> -1100 | F31: =E31/C31 -> -0.275 | G31: =IF(F31>0.1,"Over Budget",IF(F31<-0.1,"Under Budget","On Track")) -> Under Budget
A32: =Pivot!A9 -> 6 | B32: Marketing Costs | C32: =Pivot!D9 -> 4000 | D32: =VLOOKUP(A8,Pivot!$A$21:$G$32,4,0) -> 3500 | E32: =D32-C32 -> -500 | F32: =E32/C32 -> -0.125 | G32: =IF(F32>0.1,"Over Budget",IF(F32<-0.1,"Under Budget","On Track")) -> Under Budget
A33: =Pivot!A10 -> 7 | B33: Marketing Costs | C33: =Pivot!D10 -> 8000 | D33: =VLOOKUP(A9,Pivot!$A$21:$G$32,4,0) -> 3000 | E33: =D33-C33 -> -5000 | F33: =E33/C33 -> -0.625 | G33: =IF(F33>0.1,"Over Budget",IF(F33<-0.1,"Under Budget","On Track")) -> Under Budget
A34: =Pivot!A11 -> 8 | B34: Marketing Costs | C34: =Pivot!D11 -> 6000 | D34: =VLOOKUP(A10,Pivot!$A$21:$G$32,4,0) -> 5800 | E34: =D34-C34 -> -200 | F34: =E34/C34 -> -0.033333333 | G34: =IF(F34>0.1,"Over Budget",IF(F34<-0.1,"Under Budget","On Track")) -> On Track
A35: =Pivot!A12 -> 9 | B35: Marketing Costs | C35: =Pivot!D12 -> 3000 | D35: =VLOOKUP(A11,Pivot!$A$21:$G$32,4,0) -> 3000 | E35: =D35-C35 -> 0 | F35: =E35/C35 -> 0 | G35: =IF(F35>0.1,"Over Budget",IF(F35<-0.1,"Under Budget","On Track")) -> On Track
A36: =Pivot!A13 -> 10 | B36: Marketing Costs | C36: =Pivot!D13 -> 10000 | D36: =VLOOKUP(A12,Pivot!$A$21:$G$32,4,0) -> 9800 | E36: =D36-C36 -> -200 | F36: =E36/C36 -> -0.02 | G36: =IF(F36>0.1,"Over Budget",IF(F36<-0.1,"Under Budget","On Track")) -> On Track
A37: =Pivot!A14 -> 11 | B37: Marketing Costs | C37: =Pivot!D14 -> 3000 | D37: =VLOOKUP(A13,Pivot!$A$21:$G$32,4,0) -> 2900 | E37: =D37-C37 -> -100 | F37: =E37/C37 -> -0.033333333 | G37: =IF(F37>0.1,"Over Budget",IF(F37<-0.1,"Under Budget","On Track")) -> On Track
A38: =Pivot!A15 -> 12 | B38: Marketing Costs | C38: =Pivot!D15 -> 7000 | D38: =VLOOKUP(A14,Pivot!$A$21:$G$32,4,0) -> 7200 | E38: =D38-C38 -> 200 | F38: =E38/C38 -> 0.028571429 | G38: =IF(F38>0.1,"Over Budget",IF(F38<-0.1,"Under Budget","On Track")) -> On Track
A39: =Pivot!A4 -> 1 | B39: Travelling Cost | C39: =Pivot!E4 -> 4000 | D39: =VLOOKUP(A3,Pivot!$A$21:$G$32,5,0) -> 3200 | E39: =D39-C39 -> -800 | F39: =E39/C39 -> -0.2 | G39: =IF(F39>0.1,"Over Budget",IF(F39<-0.1,"Under Budget","On Track")) -> Under Budget
A40: =Pivot!A5 -> 2 | B40: Travelling Cost | C40: =Pivot!E5 -> 4000 | D40: =VLOOKUP(A4,Pivot!$A$21:$G$32,5,0) -> 2300 | E40: =D40-C40 -> -1700 | F40: =E40/C40 -> -0.425 | G40: =IF(F40>0.1,"Over Budget",IF(F40<-0.1,"Under Budget","On Track")) -> Under Budget
A41: =Pivot!A6 -> 3 | B41: Travelling Cost | C41: =Pivot!E6 -> 4000 | D41: =VLOOKUP(A5,Pivot!$A$21:$G$32,5,0) -> 5300 | E41: =D41-C41 -> 1300 | F41: =E41/C41 -> 0.325 | G41: =IF(F41>0.1,"Over Budget",IF(F41<-0.1,"Under Budget","On Track")) -> Over Budget
...

Sheet Dashboard
B2: BUDGET TRACKING DASHBOARD
B3: Budget vs Actual Analysis - 2023 - 6 Cost Categories
B5: TOTAL BUDGET | E5: TOTAL ACTUAL | H5: TOTAL VARIANCE | K5: VARIANCE %
B6: ='Budget Analysis'!B84 -> 1762200 | E6: ='Budget Analysis'!C84 -> 1718180 | H6: ='Budget Analysis'!D84 -> -44020 | K6: ='Budget Analysis'!E84 -> -0.024980138
B8: full year 2023 | E8: full year 2023 | H8: vs annual budget | K8: budget compliance
B10: ANNUAL SUMMARY BY CATEGORY
B11: Category | D11: Annual Budget | F11: Annual Actual | H11: Variance | J11: Variance % | L11: Status
B12: ='Budget Analysis'!A78 -> Development Costs | D12: ='Budget Analysis'!B78 -> 1340200 | F12: ='Budget Analysis'!C78 -> 1314635 | H12: ='Budget Analysis'!D78 -> -25565 | J12: ='Budget Analysis'!E78 -> -0.019075511 | L12: ='Budget Analysis'!F78 -> On Track
B13: ='Budget Analysis'!A79 -> Operational Costs | D13: ='Budget Analysis'!B79 -> 165000 | F13: ='Budget Analysis'!C79 -> 174082 | H13: ='Budget Analysis'!D79 -> 9082 | J13: ='Budget Analysis'!E79 -> 0.055042424 | L13: ='Budget Analysis'!F79 -> On Track
B14: ='Budget Analysis'!A80 -> Marketing Costs | D14: ='Budget Analysis'!B80 -> 75000 | F14: ='Budget Analysis'!C80 -> 69676 | H14: ='Budget Analysis'!D80 -> -5324 | J14: ='Budget Analysis'!E80 -> -0.070986667 | L14: ='Budget Analysis'!F80 -> On Track
B15: ='Budget Analysis'!A81 -> Travelling Cost | D15: ='Budget Analysis'!B81 -> 48000 | F15: ='Budget Analysis'!C81 -> 41300 | H15: ='Budget Analysis'!D81 -> -6700 | J15: ='Budget Analysis'!E81 -> -0.13958333 | L15: ='Budget Analysis'!F81 -> Under Budget
B16: ='Budget Analysis'!A82 -> Training Cost | D16: ='Budget Analysis'!B82 -> 86000 | F16: ='Budget Analysis'!C82 -> 68000 | H16: ='Budget Analysis'!D82 -> -18000 | J16: ='Budget Analysis'!E82 -> -0.20930233 | L16: ='Budget Analysis'!F82 -> Under Budget
B17: ='Budget Analysis'!A83 -> Maintenance Cost | D17: ='Budget Analysis'!B83 -> 48000 | F17: ='Budget Analysis'!C83 -> 50487 | H17: ='Budget Analysis'!D83 -> 2487 | J17: ='Budget Analysis'!E83 -> 0.0518125 | L17: ='Budget Analysis'!F83 -> On Track
B40: KEY INSIGHTS
B41: Overall budget compliance at 97.5% - total underspend of $44,020. Training Cost shows the largest deviation at -20.9%, likely due to cancelled or deferred sessions. Travelling Cost also underperformed at -14.0%. Operational and Maintenance costs exceeded budget marginally. Development Costs, the largest category at 76% of total budget, remained tightly controlled at -1.9% variance.
B45: Data source: Financial Dataset - Expenses Budget vs Actual · Kaggle · saharsyed · kaggle.com/datasets/saharsyed/financial-dataset-expenses-budget-vs-actual
